Workbook
Name NombreIntervalo1: 'PRECIO PROVEEDORES'!$A$3:$A$543

Sheet COCINA TUESTE
A1: vega
B2: YOGURT GRIEGO | G2: HUEVOS REVUELTOS | L2: PANCAKES | Q2: TOSTADAS FRANCESAS | V2: SANDWICH POLLO TERIYAKI | AA2: TOSTADO JAMON Y QUESO | AF2: HAMBURGUESA VEGAN
C3: Kg/Lt/Uni | D3: $ | E3: Total $ | H3: Kg/Lt/Uni | I3: $ | J3: Total $ | M3: Kg/Lt/Uni | N3: $ | O3: Total $ | R3: Kg/Lt/Uni | S3: $ | T3: Total $ | W3: Kg/Lt/Uni | X3: $ | Y3: Total $ | AB3: Kg/Lt/Uni | AC3: $ | AD3: Total $ | AG3: Kg/Lt/Uni | AH3: $ | AI3: Total $
B4: yogurt griego | C4: 0.15 | D4: =+VLOOKUP(B4,'PRECIO PROVEEDORES'!$A$2:$B$716,2,0) -> 7449.2 | E4: =+C4*D4 -> 1117.38 | G4: tostada en pan de campo xl | H4: 1 | I4: =+VLOOKUP(G4,'PRECIO PROVEEDORES'!$A$2:$B$716,2,0) -> 243.1 | J4: =+H4*I4 -> 243.1 | L4: pancakes | M4: 2 | N4: =+VLOOKUP(L4,'PRECIO PROVEEDORES'!$A$2:$B$716,2,0) -> 391.805 | O4: =+M4*N4 -> 783.61 | Q4: uva | R4: 0.04 | S4: =+VLOOKUP(Q4,'PRECIO PROVEEDORES'!$A$2:$B$716,2,0) -> 2332 | T4: =+R4*S4 -> 93.28 | V4: tostada en pan de campo xl | W4: 2 | X4: =+VLOOKUP(V4,'PRECIO PROVEEDORES'!$A$2:$B$716,2,0) -> 243.1 | Y4: =+W4*X4 -> 486.2 | AA4: tostada en pan de campo xl | AB4: 2 | AC4: =+VLOOKUP(AA4,'PRECIO PROVEEDORES'!$A$2:$B$716,2,0) -> 243.1 | AD4: =+AB4*AC4 -> 486.2 | AF4: pan burger vegano | AG4: 1 | AH4: =+VLOOKUP(AF4,'PRECIO PROVEEDORES'!$A$2:$B$716,2,0) -> 992.2 | AI4: =+AG4*AH4 -> 992.2
B5: granola | C5: 0.05 | D5: =+VLOOKUP(B5,'PRECIO PROVEEDORES'!$A$2:$B$716,2,0) -> 8954.3189 | E5: =+C5*D5 -> 447.71595 | G5: huevos | H5: 3 | I5: =+VLOOKUP(G5,'PRECIO PROVEEDORES'!$A$2:$B$716,2,0) -> 192 | J5: =+H5*I5 -> 576 | L5: salsa de chocolate | M5: 0.01 | N5: =+VLOOKUP(L5,'PRECIO PROVEEDORES'!$A$2:$B$716,2,0) -> 9542 | O5: =+M5*N5 -> 95.42 | Q5: Brioche para tostadas francesas | R5: 1 | S5: =+VLOOKUP(Q5,'PRECIO PROVEEDORES'!$A$2:$B$716,2,0) -> 1650 | T5: =+R5*S5 -> 1650 | V5: pollo | W5: 0.12 | X5: =+VLOOKUP(V5,'PRECIO PROVEEDORES'!$A$2:$B$716,2,0) -> 7700 | Y5: =+W5*X5 -> 924 | AA5: Fiambre, Jamon cocido | AB5: 0.06 | AC5: =+VLOOKUP(AA5,'PRECIO PROVEEDORES'!$A$2:$B$716,2,0) -> 11881 | AD5: =+AB5*AC5 -> 712.86 | AF5: Aji colorado | AG5: 0.03 | AH5: =+VLOOKUP(AF5,'PRECIO PROVEEDORES'!$A$2:$B$716,2,0) -> 4788 | AI5: =+AG5*AH5 -> 143.64
B6: banana | C6: 0.05 | D6: =+VLOOKUP(B6,'PRECIO PROVEEDORES'!$A$2:$B$716,2,0) -> 3360 | E6: =+C6*D6 -> 168 | G6: Palta hass | H6: 0.08 | I6: =+VLOOKUP(G6,'PRECIO PROVEEDORES'!$A$2:$B$716,2,0) -> 9316 | J6: =+H6*I6 -> 745.28 | L6: Banana | M6: 0.08 | N6: =+VLOOKUP(L6,'PRECIO PROVEEDORES'!$A$2:$B$716,2,0) -> 3360 | O6: =+M6*N6 -> 268.8 | Q6: queso crema paulina | R6: 0.03 | S6: =+VLOOKUP(Q6,'PRECIO PROVEEDORES'!$A$2:$B$716,2,0) -> 6000 | T6: =+R6*S6 -> 180 | V6: Lechuga, francesa | W6: 0.02 | X6: =+VLOOKUP(V6,'PRECIO PROVEEDORES'!$A$2:$B$716,2,0) -> 6440 | Y6: =+W6*X6 -> 128.8 | AA6: queso danbo tregar | AB6: 0.09 | AC6: =+VLOOKUP(AA6,'PRECIO PROVEEDORES'!$A$2:$B$716,2,0) -> 10697 | AD6: =+AB6*AC6 -> 962.73 | AF6: Hoja amarga, Rucula selvatica | AG6: 0.05 | AH6: =+VLOOKUP(AF6,'PRECIO PROVEEDORES'!$A$2:$B$716,2,0) -> 9900 | AI6: =+AG6*AH6 -> 495
B7: frutilla | C7: 0.04 | D7: =+VLOOKUP(B7,'PRECIO PROVEEDORES'!$A$2:$B$716,2,0) -> 26000 | E7: =+C7*D7 -> 1040 | G7: queso crema paulina | H7: 0.035 | I7: =+VLOOKUP(G7,'PRECIO PROVEEDORES'!$A$2:$B$716,2,0) -> 6000 | J7: =+H7*I7 -> 210 | L7: frutilla | M7: 0.05 | N7: =+VLOOKUP(L7,'PRECIO PROVEEDORES'!$A$2:$B$716,2,0) -> 26000 | O7: =+M7*N7 -> 1300 | Q7: frutilla | R7: 0.05 | S7: =+VLOOKUP(Q7,'PRECIO PROVEEDORES'!$A$2:$B$716,2,0) -> 26000 | T7: =+R7*S7 -> 1300 | V7: palta hass | W7: 0.04 | X7: =+VLOOKUP(V7,'PRECIO PROVEEDORES'!$A$2:$B$716,2,0) -> 9316 | Y7: =+W7*X7 -> 372.64 | AA7: manteca tueste alyser | AB7: 0.02 | AC7: =+VLOOKUP(AA7,'PRECIO PROVEEDORES'!$A$2:$B$716,2,0) -> 12206 | AD7: =+AB7*AC7 -> 244.12 | AF7: pesto de albahaca | AG7: 0.01 | AH7: =+VLOOKUP(AF7,'PRECIO PROVEEDORES'!$A$2:$B$716,2,0) -> 0 | AI7: =+AG7*AH7 -> 0
B8: miel alyser | C8: 0.01 | D8: =+VLOOKUP(B8,'PRECIO PROVEEDORES'!$A$2:$B$716,2,0) -> 5917 | E8: =+C8*D8 -> 59.17 | G8: Tomate cherry rojo | H8: 0.05 | I8: =+VLOOKUP(G8,'PRECIO PROVEEDORES'!$A$2:$B$716,2,0) -> 4095 | J8: =+H8*I8 -> 204.75 | L8: nutella | M8: 0.02 | N8: =+VLOOKUP(L8,'PRECIO PROVEEDORES'!$A$2:$B$716,2,0) -> 35691.97 | O8: =+M8*N8 -> 713.8394 | Q8: miel alyser | R8: 0.015 | S8: =+VLOOKUP(Q8,'PRECIO PROVEEDORES'!$A$2:$B$716,2,0) -> 5917 | T8: =+R8*S8 -> 88.755 | V8: tomate seco | W8: 0.05 | X8: =+VLOOKUP(V8,'PRECIO PROVEEDORES'!$A$2:$B$716,2,0) -> 17587.35 | Y8: =+W8*X8 -> 879.3675 | AF8: Garbanzos | AG8: 0.1 | AH8: =+VLOOKUP(AF8,'PRECIO PROVEEDORES'!$A$2:$B$716,2,0) -> 3330 | AI8: =+AG8*AH8 -> 333
B9: arandano | C9: 0.01 | D9: =+VLOOKUP(B9,'PRECIO PROVEEDORES'!$A$2:$B$716,2,0) -> 56000 | E9: =+C9*D9 -> 560 | G9: Fiambre, Panceta ahumada | H9: 0.02 | I9: =+VLOOKUP(G9,'PRECIO PROVEEDORES'!$A$2:$B$716,2,0) -> 18256.35 | J9: =+H9*I9 -> 365.127 | Q9: Hierbas frescas, Menta bariada | R9: 0.002 | S9: =+VLOOKUP(Q9,'PRECIO PROVEEDORES'!$A$2:$B$716,2,0) -> 18304 | T9: =+R9*S9 -> 36.608 | V9: salsa teriyaki | W9: 0.05 | X9: =+VLOOKUP(V9,'PRECIO PROVEEDORES'!$A$2:$B$716,2,0) -> 2910.45 | Y9: =+W9*X9 -> 145.5225 | AF9: cebolla | AG9: 0.06 | AH9: =+VLOOKUP(AF9,'PRECIO PROVEEDORES'!$A$2:$B$716,2,0) -> 1092.5 | AI9: =+AG9*AH9 -> 65.55
Q10: manteca tueste alyser | R10: 0.01 | S10: =+VLOOKUP(Q10,'PRECIO PROVEEDORES'!$A$2:$B$716,2,0) -> 12206 | T10: =+R10*S10 -> 122.06 | V10: queso danbo tregar | W10: 0.02 | X10: =+VLOOKUP(V10,'PRECIO PROVEEDORES'!$A$2:$B$716,2,0) -> 10697 | Y10: =+W10*X10 -> 213.94 | AF10: Hierbas frescas, Menta bariada | AG10: 0.1 | AH10: =+VLOOKUP(AF10,'PRECIO PROVEEDORES'!$A$2:$B$716,2,0) -> 18304 | AI10: =+AG10*AH10 -> 1830.4
Q11: kiwi | R11: 0.05 | S11: =+VLOOKUP(Q11,'PRECIO PROVEEDORES'!$A$2:$B$716,2,0) -> 10450 | T11: =+R11*S11 -> 522.5 | V11: queso reggianito | W11: 0.015 | X11: =+VLOOKUP(V11,'PRECIO PROVEEDORES'!$A$2:$B$716,2,0) -> 17376 | Y11: =+W11*X11 -> 260.64 | AF11: comino | AG11: 0.002 | AH11: =+VLOOKUP(AF11,'PRECIO PROVEEDORES'!$A$2:$B$716,2,0) -> 10164 | AI11: =+AG11*AH11 -> 20.328
Q12: ciruela | R12: 0.05 | S12: =+VLOOKUP(Q12,'PRECIO PROVEEDORES'!$A$2:$B$716,2,0) -> 4860 | T12: =+R12*S12 -> 243 | V12: papas asadas | W12: 0.15 | X12: =+VLOOKUP(V12,'PRECIO PROVEEDORES'!$A$2:$B$716,2,0) -> 1685.0215 | Y12: =+W12*X12 -> 252.75322 | AF12: sal fina | AG12: 0.002 | AH12: =+VLOOKUP(AF12,'PRECIO PROVEEDORES'!$A$2:$B$716,2,0) -> 1633 | AI12: =+AG12*AH12 -> 3.266
V13: mayonesa de pimiento | W13: 0.04 | X13: =+VLOOKUP(V13,'PRECIO PROVEEDORES'!$A$2:$B$716,2,0) -> 3891.911 | Y13: =+W13*X13 -> 155.67644 | AF13: Pimienta negra en granos | AG13: 0.002 | AH13: =+VLOOKUP(AF13,'PRECIO PROVEEDORES'!$A$2:$B$716,2,0) -> 22269 | AI13: =+AG13*AH13 -> 44.538
AF14: papas asadas | AG14: 0.15 | AH14: =+VLOOKUP(AF14,'PRECIO PROVEEDORES'!$A$2:$B$716,2,0) -> 1685.0215 | AI14: =+AG14*AH14 -> 252.75322
AF15: mayonesa de pimiento | AG15: 0.04 | AH15: =+VLOOKUP(AF15,'PRECIO PROVEEDORES'!$A$2:$B$716,2,0) -> 3891.911 | AI15: =+AG15*AH15 -> 155.67644
B19: Costo Total de la materia prima | E19: =SUM(E4:E18) -> 3392.2659 | G19: Costo Total de la materia prima | J19: =SUM(J4:J18) -> 2344.257 | L19: Costo Total de la materia prima | O19: =SUM(O4:O18) -> 3161.6694 | Q19: Costo Total de la materia prima | T19: =SUM(T4:T18) -> 4236.203 | V19: Costo Total de la materia prima | Y19: =SUM(Y4:Y18) -> 3819.5397 | AA19: Costo Total de la materia prima | AD19: =SUM(AD4:AD18) -> 2405.91 | AF19: Costo Total de la materia prima | AI19: =SUM(AI4:AI18) -> 4336.3517
B20: Costo total de la preparación | E20: =SUM(E19) -> 3392.2659 | G20: Costo total de la preparación | J20: =SUM(J19) -> 2344.257 | L20: Costo total de la preparación | O20: =SUM(O19) -> 3161.6694 | Q20: Costo total de la preparación | T20: =SUM(T19) -> 4236.203 | V20: Costo total de la preparación | Y20: =SUM(Y19) -> 3819.5397 | AA20: Costo total de la preparación | AD20: =SUM(AD19) -> 2405.91 | AF20: Costo total de la preparación | AI20: =SUM(AI19) -> 4336.3517
B21: Costo porción | E21: =+E20 -> 3392.2659 | G21: Costo porción | J21: =+J20 -> 2344.257 | L21: Costo porción | O21: =+O20 -> 3161.6694 | Q21: Costo porción | T21: =+T20 -> 4236.203 | V21: Costo porción | Y21: =+Y20 -> 3819.5397 | AA21: Costo porción | AD21: =+AD20 -> 2405.91 | AF21: Costo porción | AI21: =+AI20 -> 4336.3517
B22: Porcentaje costo materia prima establecida | D22: 0.3 | G22: Porcentaje costo materia prima establecida | I22: 0.3 | L22: Porcentaje costo materia prima establecida | N22: 0.3 | Q22: Porcentaje costo materia prima establecida | S22: 0.3 | V22: Porcentaje costo materia prima establecida | X22: 0.3 | AA22: Porcentaje costo materia prima establecida | AC22: 0.3 | AF22: Porcentaje costo materia prima establecida | AH22: 0.3
B23: Precio potencial de venta | E23: =+E21*3.33333333333333 -> 11307.553 | G23: Precio potencial de venta | J23: =+J21*3.33333333333333 -> 7814.19 | L23: Precio potencial de venta | O23: =+O21*3.33333333333333 -> 10538.898 | Q23: Precio potencial de venta | T23: =+T21*3.33333333333333 -> 14120.677 | V23: Precio potencial de venta | Y23: =+Y21*3.33333333333333 -> 12731.799 | AA23: Precio potencial de venta | AD23: =+AD21*3.33333333333333 -> 8019.7 | AF23: Precio potencial de venta | AI23: =+AI21*3.33333333333333 -> 14454.506
B24: Precio de Venta | E24: 15000 | G24: Precio de Venta | J24: 15000 | L24: Precio de Venta | O24: 17000 | Q24: Precio de Venta | T24: 17500 | V24: Precio de Venta | Y24: 19000 | AA24: Precio de Venta | AD24: 14000 | AF24: Precio de Venta | AH24: 15000 | AI24: 17000
E25: =+E24-E23 -> 3692.4468 | J25: =+J24-J23 -> 7185.81 | O25: =+O24-O23 -> 6461.102 | T25: =+T24-T23 -> 3379.3233 | Y25: =+Y24-Y23 -> 6268.2011 | AD25: =+AD24-AD23 -> 5980.3 | AI25: =+AI24-AI23 -> 2545.4945
B26: Costo Real MP | E26: =E21/E24 -> 0.22615106 | G26: Costo Real MP | J26: =J21/J24 -> 0.1562838 | L26: Costo Real MP | O26: =O21/O24 -> 0.18598055 | Q26: Costo Real MP | T26: =T21/T24 -> 0.24206874 | V26: Costo Real MP | Y26: =Y21/Y24 -> 0.2010284 | AA26: Costo Real MP | AD26: =AD21/AD24 -> 0.17185071 | AF26: Costo Real MP | AI26: =AI21/AI24 -> 0.25507951
B29: TOSTON TUESTE | G29: TOSTON PALTA | L29: TOSTADO PAN CHIPA | Q29: TAPA DE ASADO | V29: SANDWICH BRIE | AA29: TOSTADO LOMITO Y CHEDAR | AF29: CHIPA CLASICO
C30: Kg/Lt/Uni | D30: $ | E30: Total $ | H30: Kg/Lt/Uni | I30: $ | J30: Total $ | M30: Kg/Lt/Uni | N30: $ | O30: Total $ | R30: Kg/Lt/Uni | S30: $ | T30: Total $ | W30: Kg/Lt/Uni | X30: $ | Y30: Total $ | AB30: Kg/Lt/Uni | AC30: $ | AD30: Total $ | AG30: Kg/Lt/Uni | AH30: $ | AI30: Total $
B31: rodaja pan masa madre | C31: 1 | D31: =+VLOOKUP(B31,'PRECIO PROVEEDORES'!$A$2:$B$716,2,0) -> 1252.8 | E31: =+C31*D31 -> 1252.8 | G31: rodaja pan masa madre | H31: 1 | I31: =+VLOOKUP(G31,'PRECIO PROVEEDORES'!$A$2:$B$716,2,0) -> 1252.8 | J31: =+H31*I31 -> 1252.8 | L31: pan de chipa | M31: 0.18 | N31: =+VLOOKUP(L31,'PRECIO PROVEEDORES'!$A$2:$B$716,2,0) -> 8843.4185 | O31: =+M31*N31 -> 1591.8153 | Q31: tapa de asado | R31: 0.15 | S31: =+VLOOKUP(Q31,'PRECIO PROVEEDORES'!$A$2:$B$716,2,0) -> 17289 | T31: =+R31*S31 -> 2593.35 | V31: pan ciabatta | W31: 1 | X31: =+VLOOKUP(V31,'PRECIO PROVEEDORES'!$A$2:$B$716,2,0) -> 168.4551 | Y31: =+W31*X31 -> 168.4551 | AA31: pan de papa | AB31: 1 | AC31: =+VLOOKUP(AA31,'PRECIO PROVEEDORES'!$A$2:$B$716,2,0) -> 675 | AD31: =+AB31*AC31 -> 675 | AF31: chipa clasico | AG31: 1 | AH31: =+VLOOKUP(AF31,'PRECIO PROVEEDORES'!$A$2:$B$716,2,0) -> 8843.4185 | AI31: =+AG31*AH31 -> 8843.4185
B32: Hoja amarga, Rucula selvatica | C32: 0.03 | D32: =+VLOOKUP(B32,'PRECIO PROVEEDORES'!$A$2:$B$716,2,0) -> 9900 | E32: =+C32*D32 -> 297 | G32: queso crema paulina | H32: 0.05 | I32: =+VLOOKUP(G32,'PRECIO PROVEEDORES'!$A$2:$B$716,2,0) -> 6000 | J32: =+H32*I32 -> 300 | L32: Fiambre, Jamon cocido | M32: 0.06 | N32: =+VLOOKUP(L32,'PRECIO PROVEEDORES'!$A$2:$B$716,2,0) -> 11881 | O32: =+M32*N32 -> 712.86 | Q32: pan pretzalej | R32: 1 | S32: =+VLOOKUP(Q32,'PRECIO PROVEEDORES'!$A$2:$B$716,2,0) -> 531 | T32: =+R32*S32 -> 531 | V32: Hoja amarga, Rucula selvatica | W32: 0.04 | X32: =+VLOOKUP(V32,'PRECIO PROVEEDORES'!$A$2:$B$716,2,0) -> 9900 | Y32: =+W32*X32 -> 396 | AA32: Cheddar feteado | AB32: 0.05 | AC32: =+VLOOKUP(AA32,'PRECIO PROVEEDORES'!$A$2:$B$716,2,0) -> 16343 | AD32: =+AB32*AC32 -> 817.15
B33: frutilla | C33: 0.04 | D33: =+VLOOKUP(B33,'PRECIO PROVEEDORES'!$A$2:$B$716,2,0) -> 26000 | E33: =+C33*D33 -> 1040 | G33: palta hass | H33: 0.08 | I33: =+VLOOKUP(G33,'PRECIO PROVEEDORES'!$A$2:$B$716,2,0) -> 9316 | J33: =+H33*I33 -> 745.28 | L33: queso danbo tregar | M33: 0.09 | N33: =+VLOOKUP(L33,'PRECIO PROVEEDORES'!$A$2:$B$716,2,0) -> 10697 | O33: =+M33*N33 -> 962.73 | Q33: barbacoa | R33: 0.03 | S33: =+VLOOKUP(Q33,'PRECIO PROVEEDORES'!$A$2:$B$716,2,0) -> 4800 | T33: =+R33*S33 -> 144 | V33: tomate seco | W33: 0.02 | X33: =+VLOOKUP(V33,'PRECIO PROVEEDORES'!$A$2:$B$716,2,0) -> 17587.35 | Y33: =+W33*X33 -> 351.747 | AA33: Fiambre, Lomito ahumado | AB33: 0.06 | AC33: =+VLOOKUP(AA33,'PRECIO PROVEEDORES'!$A$2:$B$716,2,0) -> 15813 | AD33: =+AB33*AC33 -> 948.78
B34: garrapiñada zapallo | C34: 0.015 | D34: =+VLOOKUP(B34,'PRECIO PROVEEDORES'!$A$2:$B$716,2,0) -> 16260 | E34: =+C34*D34 -> 243.9 | G34: Alcaparras | H34: 0.007 | I34: =+VLOOKUP(G34,'PRECIO PROVEEDORES'!$A$2:$B$716,2,0) -> 24435.611 | J34: =+H34*I34 -> 171.04928 | L34: pesto de tomate | M34: 0.025 | N34: =+VLOOKUP(L34,'PRECIO PROVEEDORES'!$A$2:$B$716,2,0) -> 37116.005 | O34: =+M34*N34 -> 927.90013 | Q34: cebollas encurtidas | R34: 0.01 | S34: =+VLOOKUP(Q34,'PRECIO PROVEEDORES'!$A$2:$B$716,2,0) -> 2381.6561 | T34: =+R34*S34 -> 23.816561 | V34: queso brie | W34: 0.08 | X34: =+VLOOKUP(V34,'PRECIO PROVEEDORES'!$A$2:$B$716,2,0) -> 20535 | Y34: =+W34*X34 -> 1642.8
B35: queso brie | C35: 0.04 | D35: =+VLOOKUP(B35,'PRECIO PROVEEDORES'!$A$2:$B$716,2,0) -> 20535 | E35: =+C35*D35 -> 821.4 | G35: Aceto balsamico reduccion | H35: 0.003 | I35: =+VLOOKUP(G35,'PRECIO PROVEEDORES'!$A$2:$B$716,2,0) -> 10601.56 | J35: =+H35*I35 -> 31.80468 | L35: pesto de albahaca | M35: 0.01 | N35: =+VLOOKUP(L35,'PRECIO PROVEEDORES'!$A$2:$B$716,2,0) -> 0 | O35: =+M35*N35 -> 0 | Q35: papas asadas | R35: 0.15 | S35: =+VLOOKUP(Q35,'PRECIO PROVEEDORES'!$A$2:$B$716,2,0) -> 1685.0215 | T35: =+R35*S35 -> 252.75322 | V35: mermelada de morron | W35: 0.03 | X35: =+VLOOKUP(V35,'PRECIO PROVEEDORES'!$A$2:$B$716,2,0) -> 4622.4709 | Y35: =+W35*X35 -> 138.67413
B36: miel alyser | C36: 0.01 | D36: =+VLOOKUP(B36,'PRECIO PROVEEDORES'!$A$2:$B$716,2,0) -> 5917 | E36: =+C36*D36 -> 59.17 | G36: Mix de semillas | H36: 0.003 | I36: =+VLOOKUP(G36,'PRECIO PROVEEDORES'!$A$2:$B$716,2,0) -> 5952.89 | J36: =+H36*I36 -> 17.85867 | Q36: mayonesa de pimiento | R36: 0.04 | S36: =+VLOOKUP(Q36,'PRECIO PROVEEDORES'!$A$2:$B$716,2,0) -> 3891.911 | T36: =+R36*S36 -> 155.67644 | V36: papas asadas | W36: 0.15 | X36: =+VLOOKUP(V36,'PRECIO PROVEEDORES'!$A$2:$B$716,2,0) -> 1685.0215 | Y36: =+W36*X36 -> 252.75322
G37: flores comestibles | H37: 0.001 | I37: =+VLOOKUP(G37,'PRECIO PROVEEDORES'!$A$2:$B$716,2,0) -> 5033.6 | J37: =+H37*I37 -> 5.0336 | V37: mayonesa de pimiento | W37: 0.04 | X37: =+VLOOKUP(V37,'PRECIO PROVEEDORES'!$A$2:$B$716,2,0) -> 3891.911 | Y37: =+W37*X37 -> 155.67644
B46: Costo Total de la materia prima | E46: =SUM(E31:E45) -> 3714.27 | G46: Costo Total de la materia prima | J46: =SUM(J31:J45) -> 2523.8262 | L46: Costo Total de la materia prima | O46: =SUM(O31:O45) -> 4195.3055 | Q46: Costo Total de la materia prima | T46: =SUM(T31:T45) -> 3700.5962 | V46: Costo Total de la materia prima | Y46: =SUM(Y31:Y45) -> 3106.1059 | AA46: Costo Total de la materia prima | AD46: =SUM(AD31:AD45) -> 2440.93 | AF46: Costo Total de la materia prima | AI46: =SUM(AI31:AI45) -> 8843.4185
B47: Costo total de la preparación | E47: =SUM(E46) -> 3714.27 | G47: Costo total de la preparación | J47: =SUM(J46) -> 2523.8262 | L47: Costo total de la preparación | O47: =SUM(O46) -> 4195.3055 | Q47: Costo total de la preparación | T47: =SUM(T46) -> 3700.5962 | V47: Costo total de la preparación | Y47: =SUM(Y46) -> 3106.1059 | AA47: Costo total de la preparación | AD47: =SUM(AD46) -> 2440.93 | AF47: Costo total de la preparación | AI47: =SUM(AI46) -> 8843.4185
B48: Costo porción | E48: =+E47 -> 3714.27 | G48: Costo porción | J48: =+J47 -> 2523.8262 | L48: Costo porción | O48: =+O47 -> 4195.3055 | Q48: Costo porción | T48: =+T47 -> 3700.5962 | V48: Costo porción | Y48: =+Y47 -> 3106.1059 | AA48: Costo porción | AD48: =+AD47 -> 2440.93 | AF48: Costo porción | AI48: =+AI47 -> 8843.4185
B49: Porcentaje costo materia prima establecida | D49: 0.3 | G49: Porcentaje costo materia prima establecida | I49: 0.3 | L49: Porcentaje costo materia prima establecida | N49: 0.3 | Q49: Porcentaje costo materia prima establecida | S49: 0.3 | V49: Porcentaje costo materia prima establecida | X49: 0.3 | AA49: Porcentaje costo materia prima establecida | AC49: 0.3 | AF49: Porcentaje costo materia prima establecida | AH49: 0.3
B50: Precio potencial de venta | E50: =+E48*3.33333333333333 -> 12380.9 | G50: Precio potencial de venta | J50: =+J48*3.33333333333333 -> 8412.7541 | L50: Precio potencial de venta | O50: =+O48*3.33333333333333 -> 13984.352 | Q50: Precio potencial de venta | T50: =+T48*3.33333333333333 -> 12335.321 | V50: Precio potencial de venta | Y50: =+Y48*3.33333333333333 -> 10353.686 | AA50: Precio potencial de venta | AD50: =+AD48*3.33333333333333 -> 8136.4333 | AF50: Precio potencial de venta | AI50: =+AI48*3.33333333333333 -> 29478.062
B51: Precio de Venta | E51: 16000 | G51: Precio de Venta | J51: 15000 | L51: Precio de Venta | O51: 17000 | Q51: Precio de Venta | T51: 18500 | V51: Precio de Venta | Y51: 16500 | AA51: Precio de Venta | AD51: 12500 | AF51: Precio de Venta | AI51: 4200
E52: =+E51-E50 -> 3619.1 | J52: =+J51-J50 -> 6587.2459 | O52: =+O51-O50 -> 3015.6485 | T52: =+T51-T50 -> 6164.6792 | Y52: =+Y51-Y50 -> 6146.3137 | AD52: =+AD51-AD50 -> 4363.5667 | AI52: =+AI51-AI50 -> -25278.062
B53: Costo Real MP | E53: =E48/E51 -> 0.23214188 | G53: Costo Real MP | J53: =J48/J51 -> 0.16825508 | L53: Costo Real MP | O53: =O48/O51 -> 0.24678267 | Q53: Costo Real MP | T53: =T48/T51 -> 0.20003223 | V53: Costo Real MP | Y53: =Y48/Y51 -> 0.18824884 | AA53: Costo Real MP | AD53: =AD48/AD51 -> 0.1952744 | AF53: Costo Real MP | AI53: =AI48/AI51 -> 2.1055758
...

Sheet PRECIOS RAPPI
A1: vega
B2: YOGURT GRIEGO | G2: HUEVOS REVUELTOS | L2: PANCAKES | Q2: TOSTADAS FRANCESAS | V2: SANDWICH POLLO TERIYAKI | AA2: TOSTADO JAMON Y QUESO
C3: Kg/Lt/Uni | D3: $ | E3: Total $ | H3: Kg/Lt/Uni | I3: $ | J3: Total $ | M3: Kg/Lt/Uni | N3: $ | O3: Total $ | R3: Kg/Lt/Uni | S3: $ | T3: Total $ | W3: Kg/Lt/Uni | X3: $ | Y3: Total $ | AB3: Kg/Lt/Uni | AC3: $ | AD3: Total $
B4: yogurt griego | C4: 0.15 | D4: =+VLOOKUP(B4,'PRECIO PROVEEDORES'!$A$2:$B$716,2,0) -> 7449.2 | E4: =+C4*D4 -> 1117.38 | G4: tostada en pan de campo xl | H4: 1 | I4: =+VLOOKUP(G4,'PRECIO PROVEEDORES'!$A$2:$B$716,2,0) -> 243.1 | J4: =+H4*I4 -> 243.1 | L4: pancakes | M4: 2 | N4: =+VLOOKUP(L4,'PRECIO PROVEEDORES'!$A$2:$B$716,2,0) -> 391.805 | O4: =+M4*N4 -> 783.61 | Q4: uva | R4: 0.04 | S4: =+VLOOKUP(Q4,'PRECIO PROVEEDORES'!$A$2:$B$716,2,0) -> 2332 | T4: =+R4*S4 -> 93.28 | V4: tostada en pan de campo xl | W4: 2 | X4: =+VLOOKUP(V4,'PRECIO PROVEEDORES'!$A$2:$B$716,2,0) -> 243.1 | Y4: =+W4*X4 -> 486.2 | AA4: tostada en pan de campo xl | AB4: 2 | AC4: =+VLOOKUP(AA4,'PRECIO PROVEEDORES'!$A$2:$B$716,2,0) -> 243.1 | AD4: =+AB4*AC4 -> 486.2
B5: granola | C5: 0.05 | D5: =+VLOOKUP(B5,'PRECIO PROVEEDORES'!$A$2:$B$716,2,0) -> 8954.3189 | E5: =+C5*D5 -> 447.71595 | G5: huevos | H5: 3 | I5: =+VLOOKUP(G5,'PRECIO PROVEEDORES'!$A$2:$B$716,2,0) -> 192 | J5: =+H5*I5 -> 576 | L5: salsa de chocolate | M5: 0.01 | N5: =+VLOOKUP(L5,'PRECIO PROVEEDORES'!$A$2:$B$716,2,0) -> 9542 | O5: =+M5*N5 -> 95.42 | Q5: Brioche para tostadas francesas | R5: 1 | S5: =+VLOOKUP(Q5,'PRECIO PROVEEDORES'!$A$2:$B$716,2,0) -> 1650 | T5: =+R5*S5 -> 1650 | V5: pollo | W5: 0.12 | X5: =+VLOOKUP(V5,'PRECIO PROVEEDORES'!$A$2:$B$716,2,0) -> 7700 | Y5: =+W5*X5 -> 924 | AA5: Fiambre, Jamon cocido | AB5: 0.06 | AC5: =+VLOOKUP(AA5,'PRECIO PROVEEDORES'!$A$2:$B$716,2,0) -> 11881 | AD5: =+AB5*AC5 -> 712.86
B6: banana | C6: 0.05 | D6: =+VLOOKUP(B6,'PRECIO PROVEEDORES'!$A$2:$B$716,2,0) -> 3360 | E6: =+C6*D6 -> 168 | G6: Palta hass | H6: 0.08 | I6: =+VLOOKUP(G6,'PRECIO PROVEEDORES'!$A$2:$B$716,2,0) -> 9316 | J6: =+H6*I6 -> 745.28 | L6: Banana | M6: 0.08 | N6: =+VLOOKUP(L6,'PRECIO PROVEEDORES'!$A$2:$B$716,2,0) -> 3360 | O6: =+M6*N6 -> 268.8 | Q6: queso crema paulina | R6: 0.03 | S6: =+VLOOKUP(Q6,'PRECIO PROVEEDORES'!$A$2:$B$716,2,0) -> 6000 | T6: =+R6*S6 -> 180 | V6: Lechuga, francesa | W6: 0.02 | X6: =+VLOOKUP(V6,'PRECIO PROVEEDORES'!$A$2:$B$716,2,0) -> 6440 | Y6: =+W6*X6 -> 128.8 | AA6: queso danbo tregar | AB6: 0.09 | AC6: =+VLOOKUP(AA6,'PRECIO PROVEEDORES'!$A$2:$B$716,2,0) -> 10697 | AD6: =+AB6*AC6 -> 962.73
B7: frutilla | C7: 0.04 | D7: =+VLOOKUP(B7,'PRECIO PROVEEDORES'!$A$2:$B$716,2,0) -> 26000 | E7: =+C7*D7 -> 1040 | G7: queso crema paulina | H7: 0.035 | I7: =+VLOOKUP(G7,'PRECIO PROVEEDORES'!$A$2:$B$716,2,0) -> 6000 | J7: =+H7*I7 -> 210 | L7: frutilla | M7: 0.05 | N7: =+VLOOKUP(L7,'PRECIO PROVEEDORES'!$A$2:$B$716,2,0) -> 26000 | O7: =+M7*N7 -> 1300 | Q7: frutilla | R7: 0.05 | S7: =+VLOOKUP(Q7,'PRECIO PROVEEDORES'!$A$2:$B$716,2,0) -> 26000 | T7: =+R7*S7 -> 1300 | V7: palta hass | W7: 0.04 | X7: =+VLOOKUP(V7,'PRECIO PROVEEDORES'!$A$2:$B$716,2,0) -> 9316 | Y7: =+W7*X7 -> 372.64 | AA7: manteca tueste alyser | AB7: 0.02 | AC7: =+VLOOKUP(AA7,'PRECIO PROVEEDORES'!$A$2:$B$716,2,0) -> 12206 | AD7: =+AB7*AC7 -> 244.12
B8: miel alyser | C8: 0.01 | D8: =+VLOOKUP(B8,'PRECIO PROVEEDORES'!$A$2:$B$716,2,0) -> 5917 | E8: =+C8*D8 -> 59.17 | G8: Tomate cherry rojo | H8: 0.05 | I8: =+VLOOKUP(G8,'PRECIO PROVEEDORES'!$A$2:$B$716,2,0) -> 4095 | J8: =+H8*I8 -> 204.75 | L8: nutella | M8: 0.02 | N8: =+VLOOKUP(L8,'PRECIO PROVEEDORES'!$A$2:$B$716,2,0) -> 35691.97 | O8: =+M8*N8 -> 713.8394 | Q8: miel alyser | R8: 0.015 | S8: =+VLOOKUP(Q8,'PRECIO PROVEEDORES'!$A$2:$B$716,2,0) -> 5917 | T8: =+R8*S8 -> 88.755 | V8: tomate seco | W8: 0.05 | X8: =+VLOOKUP(V8,'PRECIO PROVEEDORES'!$A$2:$B$716,2,0) -> 17587.35 | Y8: =+W8*X8 -> 879.3675 | AA8: Papel de aluminio por lamina | AB8: 0.5 | AC8: =+VLOOKUP(AA8,'PRECIO PROVEEDORES'!$A$2:$B$716,2,0) -> 160.5 | AD8: =+AB8*AC8 -> 80.25
B9: arandano | C9: 0.01 | D9: =+VLOOKUP(B9,'PRECIO PROVEEDORES'!$A$2:$B$716,2,0) -> 56000 | E9: =+C9*D9 -> 560 | G9: Fiambre, Panceta ahumada | H9: 0.02 | I9: =+VLOOKUP(G9,'PRECIO PROVEEDORES'!$A$2:$B$716,2,0) -> 18256.35 | J9: =+H9*I9 -> 365.127 | L9: caja torta individual | M9: 0.5 | N9: =+VLOOKUP(L9,'PRECIO PROVEEDORES'!$A$2:$B$716,2,0) -> 620 | O9: =+M9*N9 -> 310 | Q9: Hierbas frescas, Menta bariada | R9: 0.002 | S9: =+VLOOKUP(Q9,'PRECIO PROVEEDORES'!$A$2:$B$716,2,0) -> 18304 | T9: =+R9*S9 -> 36.608 | V9: salsa teriyaki | W9: 0.05 | X9: =+VLOOKUP(V9,'PRECIO PROVEEDORES'!$A$2:$B$716,2,0) -> 2910.45 | Y9: =+W9*X9 -> 145.5225
B10: Bowl con tapa | C10: 0.5 | D10: =+VLOOKUP(B10,'PRECIO PROVEEDORES'!$A$2:$B$716,2,0) -> 974 | E10: =+C10*D10 -> 487 | G10: Bowl con tapa | H10: 0.5 | I10: =+VLOOKUP(G10,'PRECIO PROVEEDORES'!$A$2:$B$716,2,0) -> 974 | J10: =+H10*I10 -> 487 | Q10: manteca tueste alyser | R10: 0.01 | S10: =+VLOOKUP(Q10,'PRECIO PROVEEDORES'!$A$2:$B$716,2,0) -> 12206 | T10: =+R10*S10 -> 122.06 | V10: queso danbo tregar | W10: 0.02 | X10: =+VLOOKUP(V10,'PRECIO PROVEEDORES'!$A$2:$B$716,2,0) -> 10697 | Y10: =+W10*X10 -> 213.94
Q11: kiwi | R11: 0.05 | S11: =+VLOOKUP(Q11,'PRECIO PROVEEDORES'!$A$2:$B$716,2,0) -> 10450 | T11: =+R11*S11 -> 522.5 | V11: queso reggianito | W11: 0.015 | X11: =+VLOOKUP(V11,'PRECIO PROVEEDORES'!$A$2:$B$716,2,0) -> 17376 | Y11: =+W11*X11 -> 260.64
Q12: ciruela | R12: 0.05 | S12: =+VLOOKUP(Q12,'PRECIO PROVEEDORES'!$A$2:$B$716,2,0) -> 4860 | T12: =+R12*S12 -> 243 | V12: papas asadas | W12: 0.15 | X12: =+VLOOKUP(V12,'PRECIO PROVEEDORES'!$A$2:$B$716,2,0) -> 1685.0215 | Y12: =+W12*X12 -> 252.75322
Q13: caja torta individual | R13: 0.5 | S13: =+VLOOKUP(Q13,'PRECIO PROVEEDORES'!$A$2:$B$716,2,0) -> 620 | T13: =+R13*S13 -> 310 | V13: mayonesa de pimiento | W13: 0.04 | X13: =+VLOOKUP(V13,'PRECIO PROVEEDORES'!$A$2:$B$716,2,0) -> 3891.911 | Y13: =+W13*X13 -> 155.67644
V14: Papel de aluminio por lamina | W14: 0.5 | X14: =+VLOOKUP(V14,'PRECIO PROVEEDORES'!$A$2:$B$716,2,0) -> 160.5 | Y14: =+W14*X14 -> 80.25
V15: dip 55 cc | W15: 0.5 | X15: =+VLOOKUP(V15,'PRECIO PROVEEDORES'!$A$2:$B$716,2,0) -> 155 | Y15: =+W15*X15 -> 77.5
V16: bandeja food track n 11 | W16: 0.5 | X16: =+VLOOKUP(V16,'PRECIO PROVEEDORES'!$A$2:$B$716,2,0) -> 86 | Y16: =+W16*X16 -> 43
B19: Costo Total de la materia prima | E19: =SUM(E4:E18) -> 3879.2659 | G19: Costo Total de la materia prima | J19: =SUM(J4:J18) -> 2831.257 | L19: Costo Total de la materia prima | O19: =SUM(O4:O18) -> 3471.6694 | Q19: Costo Total de la materia prima | T19: =SUM(T4:T18) -> 4546.203 | V19: Costo Total de la materia prima | Y19: =SUM(Y4:Y18) -> 4020.2897 | AA19: Costo Total de la materia prima | AD19: =SUM(AD4:AD18) -> 2486.16
B20: Costo total de la preparación | E20: =SUM(E19) -> 3879.2659 | G20: Costo total de la preparación | J20: =SUM(J19) -> 2831.257 | L20: Costo total de la preparación | O20: =SUM(O19) -> 3471.6694 | Q20: Costo total de la preparación | T20: =SUM(T19) -> 4546.203 | V20: Costo total de la preparación | Y20: =SUM(Y19) -> 4020.2897 | AA20: Costo total de la preparación | AD20: =SUM(AD19) -> 2486.16
B21: Costo porción | E21: =+E20 -> 3879.2659 | G21: Costo porción | J21: =+J20 -> 2831.257 | L21: Costo porción | O21: =+O20 -> 3471.6694 | Q21: Costo porción | T21: =+T20 -> 4546.203 | V21: Costo porción | Y21: =+Y20 -> 4020.2897 | AA21: Costo porción | AD21: =+AD20 -> 2486.16
B22: Porcentaje costo materia prima establecida | D22: 0.3 | G22: Porcentaje costo materia prima establecida | I22: 0.3 | L22: Porcentaje costo materia prima establecida | N22: 0.3 | Q22: Porcentaje costo materia prima establecida | S22: 0.3 | V22: Porcentaje costo materia prima establecida | X22: 0.3 | AA22: Porcentaje costo materia prima establecida | AC22: 0.3
B23: Precio potencial de venta | E23: =+E21*3.33333333333333 -> 12930.886 | G23: Precio potencial de venta | J23: =+J21*3.33333333333333 -> 9437.5233 | L23: Precio potencial de venta | O23: =+O21*3.33333333333333 -> 11572.231 | Q23: Precio potencial de venta | T23: =+T21*3.33333333333333 -> 15154.01 | V23: Precio potencial de venta | Y23: =+Y21*3.33333333333333 -> 13400.966 | AA23: Precio potencial de venta | AD23: =+AD21*3.33333333333333 -> 8287.2
B24: Precio de Venta rappi | C24: 13500 | D24: 0.35 | E24: 18225 | G24: Precio de Venta rappi | H24: 12000 | I24: 0.35 | J24: 16200 | L24: Precio de Venta rappi | M24: 13000 | N24: 0.35 | O24: 17550 | Q24: Precio de Venta rappi | R24: 16000 | S24: 0.35 | T24: 21600 | V24: Precio de Venta rappi | W24: 15500 | X24: 0.35 | Y24: 21000 | AA24: Precio de Venta rappi | AB24: 11000 | AC24: 0.35 | AD24: 15000
E25: =+E24-E23 -> 5294.1135 | J25: =+J24-J23 -> 6762.4767 | O25: =+O24-O23 -> 5977.7687 | T25: =+T24-T23 -> 6445.99 | Y25: =+Y24-Y23 -> 7599.0345 | AD25: =+AD24-AD23 -> 6712.8
B26: Costo Real MP | E26: =E21/E24 -> 0.2128541 | G26: Costo Real MP | J26: =J21/J24 -> 0.17476895 | L26: Costo Real MP | O26: =O21/O24 -> 0.19781592 | Q26: Costo Real MP | T26: =T21/T24 -> 0.21047236 | V26: Costo Real MP | Y26: =Y21/Y24 -> 0.19144237 | AA26: Costo Real MP | AD26: =AD21/AD24 -> 0.165744
B29: TOSTON TUESTE | G29: TOSTON PALTA | L29: TOSTADO PAN CHIPA | Q29: TAPA DE ASADO | V29: SANDWICH BRIE | AA29: TOSTADO LOMITO Y CHEDAR | AF29: CHIPA CLASICO
C30: Kg/Lt/Uni | D30: $ | E30: Total $ | H30: Kg/Lt/Uni | I30: $ | J30: Total $ | M30: Kg/Lt/Uni | N30: $ | O30: Total $ | R30: Kg/Lt/Uni | S30: $ | T30: Total $ | W30: Kg/Lt/Uni | X30: $ | Y30: Total $ | AB30: Kg/Lt/Uni | AC30: $ | AD30: Total $ | AG30: Kg/Lt/Uni | AH30: $ | AI30: Total $
B31: rodaja pan masa madre | C31: 1 | D31: =+VLOOKUP(B31,'PRECIO PROVEEDORES'!$A$2:$B$716,2,0) -> 1252.8 | E31: =+C31*D31 -> 1252.8 | G31: rodaja pan masa madre | H31: 1 | I31: =+VLOOKUP(G31,'PRECIO PROVEEDORES'!$A$2:$B$716,2,0) -> 1252.8 | J31: =+H31*I31 -> 1252.8 | L31: pan de chipa | M31: 0.18 | N31: =+VLOOKUP(L31,'PRECIO PROVEEDORES'!$A$2:$B$716,2,0) -> 8843.4185 | O31: =+M31*N31 -> 1591.8153 | Q31: tapa de asado | R31: 0.15 | S31: =+VLOOKUP(Q31,'PRECIO PROVEEDORES'!$A$2:$B$716,2,0) -> 17289 | T31: =+R31*S31 -> 2593.35 | V31: pan ciabatta | W31: 1 | X31: =+VLOOKUP(V31,'PRECIO PROVEEDORES'!$A$2:$B$716,2,0) -> 168.4551 | Y31: =+W31*X31 -> 168.4551 | AA31: pan de papa | AB31: 1 | AC31: =+VLOOKUP(AA31,'PRECIO PROVEEDORES'!$A$2:$B$716,2,0) -> 675 | AD31: =+AB31*AC31 -> 675 | AF31: chipa clasico | AG31: 0.09 | AH31: =+VLOOKUP(AF31,'PRECIO PROVEEDORES'!$A$2:$B$716,2,0) -> 8843.4185 | AI31: =+AG31*AH31 -> 795.90767
B32: Hoja amarga, Rucula selvatica | C32: 0.03 | D32: =+VLOOKUP(B32,'PRECIO PROVEEDORES'!$A$2:$B$716,2,0) -> 9900 | E32: =+C32*D32 -> 297 | G32: queso crema paulina | H32: 0.05 | I32: =+VLOOKUP(G32,'PRECIO PROVEEDORES'!$A$2:$B$716,2,0) -> 6000 | J32: =+H32*I32 -> 300 | L32: Fiambre, Jamon cocido | M32: 0.06 | N32: =+VLOOKUP(L32,'PRECIO PROVEEDORES'!$A$2:$B$716,2,0) -> 11881 | O32: =+M32*N32 -> 712.86 | Q32: pan pretzalej | R32: 1 | S32: =+VLOOKUP(Q32,'PRECIO PROVEEDORES'!$A$2:$B$716,2,0) -> 531 | T32: =+R32*S32 -> 531 | V32: Hoja amarga, Rucula selvatica | W32: 0.04 | X32: =+VLOOKUP(V32,'PRECIO PROVEEDORES'!$A$2:$B$716,2,0) -> 9900 | Y32: =+W32*X32 -> 396 | AA32: Cheddar feteado | AB32: 0.05 | AC32: =+VLOOKUP(AA32,'PRECIO PROVEEDORES'!$A$2:$B$716,2,0) -> 16343 | AD32: =+AB32*AC32 -> 817.15
B33: frutilla | C33: 0.04 | D33: =+VLOOKUP(B33,'PRECIO PROVEEDORES'!$A$2:$B$716,2,0) -> 26000 | E33: =+C33*D33 -> 1040 | G33: palta hass | H33: 0.08 | I33: =+VLOOKUP(G33,'PRECIO PROVEEDORES'!$A$2:$B$716,2,0) -> 9316 | J33: =+H33*I33 -> 745.28 | L33: queso danbo tregar | M33: 0.09 | N33: =+VLOOKUP(L33,'PRECIO PROVEEDORES'!$A$2:$B$716,2,0) -> 10697 | O33: =+M33*N33 -> 962.73 | Q33: barbacoa | R33: 0.03 | S33: =+VLOOKUP(Q33,'PRECIO PROVEEDORES'!$A$2:$B$716,2,0) -> 4800 | T33: =+R33*S33 -> 144 | V33: tomate seco | W33: 0.02 | X33: =+VLOOKUP(V33,'PRECIO PROVEEDORES'!$A$2:$B$716,2,0) -> 17587.35 | Y33: =+W33*X33 -> 351.747 | AA33: Fiambre, Lomito ahumado | AB33: 0.06 | AC33: =+VLOOKUP(AA33,'PRECIO PROVEEDORES'!$A$2:$B$716,2,0) -> 15813 | AD33: =+AB33*AC33 -> 948.78
B34: garrapiñada zapallo | C34: 0.015 | D34: =+VLOOKUP(B34,'PRECIO PROVEEDORES'!$A$2:$B$716,2,0) -> 16260 | E34: =+C34*D34 -> 243.9 | G34: Alcaparras | H34: 0.007 | I34: =+VLOOKUP(G34,'PRECIO PROVEEDORES'!$A$2:$B$716,2,0) -> 24435.611 | J34: =+H34*I34 -> 171.04928 | L34: pesto de tomate | M34: 0.025 | N34: =+VLOOKUP(L34,'PRECIO PROVEEDORES'!$A$2:$B$716,2,0) -> 37116.005 | O34: =+M34*N34 -> 927.90013 | Q34: cebollas encurtidas | R34: 0.01 | S34: =+VLOOKUP(Q34,'PRECIO PROVEEDORES'!$A$2:$B$716,2,0) -> 2381.6561 | T34: =+R34*S34 -> 23.816561 | V34: queso brie | W34: 0.08 | X34: =+VLOOKUP(V34,'PRECIO PROVEEDORES'!$A$2:$B$716,2,0) -> 20535 | Y34: =+W34*X34 -> 1642.8 | AA34: Papel de aluminio por lamina | AB34: 0.5 | AC34: =+VLOOKUP(AA34,'PRECIO PROVEEDORES'!$A$2:$B$716,2,0) -> 160.5 | AD34: =+AB34*AC34 -> 80.25
B35: queso brie | C35: 0.04 | D35: =+VLOOKUP(B35,'PRECIO PROVEEDORES'!$A$2:$B$716,2,0) -> 20535 | E35: =+C35*D35 -> 821.4 | G35: Aceto balsamico reduccion | H35: 0.003 | I35: =+VLOOKUP(G35,'PRECIO PROVEEDORES'!$A$2:$B$716,2,0) -> 10601.56 | J35: =+H35*I35 -> 31.80468 | L35: pesto de albahaca | M35: 0.01 | N35: =+VLOOKUP(L35,'PRECIO PROVEEDORES'!$A$2:$B$716,2,0) -> 0 | O35: =+M35*N35 -> 0 | Q35: papas asadas | R35: 0.15 | S35: =+VLOOKUP(Q35,'PRECIO PROVEEDORES'!$A$2:$B$716,2,0) -> 1685.0215 | T35: =+R35*S35 -> 252.75322 | V35: mermelada de morron | W35: 0.03 | X35: =+VLOOKUP(V35,'PRECIO PROVEEDORES'!$A$2:$B$716,2,0) -> 4622.4709 | Y35: =+W35*X35 -> 138.67413
B36: miel alyser | C36: 0.01 | D36: =+VLOOKUP(B36,'PRECIO PROVEEDORES'!$A$2:$B$716,2,0) -> 5917 | E36: =+C36*D36 -> 59.17 | G36: Mix de semillas | H36: 0.003 | I36: =+VLOOKUP(G36,'PRECIO PROVEEDORES'!$A$2:$B$716,2,0) -> 5952.89 | J36: =+H36*I36 -> 17.85867 | L36: Papel de aluminio por lamina | M36: 0.5 | N36: =+VLOOKUP(L36,'PRECIO PROVEEDORES'!$A$2:$B$716,2,0) -> 160.5 | O36: =+M36*N36 -> 80.25 | Q36: mayonesa de pimiento | R36: 0.04 | S36: =+VLOOKUP(Q36,'PRECIO PROVEEDORES'!$A$2:$B$716,2,0) -> 3891.911 | T36: =+R36*S36 -> 155.67644 | V36: papas asadas | W36: 0.15 | X36: =+VLOOKUP(V36,'PRECIO PROVEEDORES'!$A$2:$B$716,2,0) -> 1685.0215 | Y36: =+W36*X36 -> 252.75322
B37: bandeja food track n 11 | C37: 0.5 | D37: =+VLOOKUP(B37,'PRECIO PROVEEDORES'!$A$2:$B$716,2,0) -> 86 | E37: =+C37*D37 -> 43 | G37: flores comestibles | H37: 0.001 | I37: =+VLOOKUP(G37,'PRECIO PROVEEDORES'!$A$2:$B$716,2,0) -> 5033.6 | J37: =+H37*I37 -> 5.0336 | Q37: Papel de aluminio por lamina | R37: 0.5 | S37: =+VLOOKUP(Q37,'PRECIO PROVEEDORES'!$A$2:$B$716,2,0) -> 160.5 | T37: =+R37*S37 -> 80.25 | V37: mayonesa de pimiento | W37: 0.04 | X37: =+VLOOKUP(V37,'PRECIO PROVEEDORES'!$A$2:$B$716,2,0) -> 3891.911 | Y37: =+W37*X37 -> 155.67644
G38: bandeja food track n 11 | H38: 0.5 | I38: =+VLOOKUP(G38,'PRECIO PROVEEDORES'!$A$2:$B$716,2,0) -> 86 | J38: =+H38*I38 -> 43 | Q38: dip 55 cc | R38: 0.5 | S38: =+VLOOKUP(Q38,'PRECIO PROVEEDORES'!$A$2:$B$716,2,0) -> 155 | T38: =+R38*S38 -> 77.5 | V38: Papel de aluminio por lamina | W38: 0.5 | X38: =+VLOOKUP(V38,'PRECIO PROVEEDORES'!$A$2:$B$716,2,0) -> 160.5 | Y38: =+W38*X38 -> 80.25
Q39: bandeja food track n 11 | R39: 0.5 | S39: =+VLOOKUP(Q39,'PRECIO PROVEEDORES'!$A$2:$B$716,2,0) -> 86 | T39: =+R39*S39 -> 43 | V39: dip 55 cc | W39: 0.5 | X39: =+VLOOKUP(V39,'PRECIO PROVEEDORES'!$A$2:$B$716,2,0) -> 155 | Y39: =+W39*X39 -> 77.5
V40: bandeja food track n 11 | W40: 0.5 | X40: =+VLOOKUP(V40,'PRECIO PROVEEDORES'!$A$2:$B$716,2,0) -> 86 | Y40: =+W40*X40 -> 43
B46: Costo Total de la materia prima | E46: =SUM(E31:E45) -> 3757.27 | G46: Costo Total de la materia prima | J46: =SUM(J31:J45) -> 2566.8262 | L46: Costo Total de la materia prima | O46: =SUM(O31:O45) -> 4275.5555 | Q46: Costo Total de la materia prima | T46: =SUM(T31:T45) -> 3901.3462 | V46: Costo Total de la materia prima | Y46: =SUM(Y31:Y45) -> 3306.8559 | AA46: Costo Total de la materia prima | AD46: =SUM(AD31:AD45) -> 2521.18 | AF46: Costo Total de la materia prima | AI46: =SUM(AI31:AI45) -> 795.90767
B47: Costo total de la preparación | E47: =SUM(E46) -> 3757.27 | G47: Costo total de la preparación | J47: =SUM(J46) -> 2566.8262 | L47: Costo total de la preparación | O47: =SUM(O46) -> 4275.5555 | Q47: Costo total de la preparación | T47: =SUM(T46) -> 3901.3462 | V47: Costo total de la preparación | Y47: =SUM(Y46) -> 3306.8559 | AA47: Costo total de la preparación | AD47: =SUM(AD46) -> 2521.18 | AF47: Costo total de la preparación | AI47: =SUM(AI46) -> 795.90767
B48: Costo porción | E48: =+E47 -> 3757.27 | G48: Costo porción | J48: =+J47 -> 2566.8262 | L48: Costo porción | O48: =+O47 -> 4275.5555 | Q48: Costo porción | T48: =+T47 -> 3901.3462 | V48: Costo porción | Y48: =+Y47 -> 3306.8559 | AA48: Costo porción | AD48: =+AD47 -> 2521.18 | AF48: Costo porción | AI48: =+AI47 -> 795.90767
B49: Porcentaje costo materia prima establecida | D49: 0.3 | G49: Porcentaje costo materia prima establecida | I49: 0.3 | L49: Porcentaje costo materia prima establecida | N49: 0.3 | Q49: Porcentaje costo materia prima establecida | S49: 0.3 | V49: Porcentaje costo materia prima establecida | X49: 0.3 | AA49: Porcentaje costo materia prima establecida | AC49: 0.3 | AF49: Porcentaje costo materia prima establecida | AH49: 0.3
...

Sheet CAFETERIA TUESTE
B2: FLAT WHITE | G2: LATTE | L2: CAPPUCINO | Q2: CORTADO TUESTE
C3: Kg/Lt/Uni | D3: $ | E3: Total $ | H3: Kg/Lt/Uni | I3: $ | J3: Total $ | M3: Kg/Lt/Uni | N3: $ | O3: Total $ | R3: Kg/Lt/Uni | S3: $ | T3: Total $
B4: Café | C4: 0.019 | D4: =+VLOOKUP(B4,'PRECIO PROVEEDORES'!$A$2:$B$716,2,0) -> 47093 | E4: =+C4*D4 -> 894.767 | G4: Café | H4: 0.01 | I4: =+VLOOKUP(G4,'PRECIO PROVEEDORES'!$A$2:$B$716,2,0) -> 47093 | J4: =+H4*I4 -> 470.93 | L4: Café | M4: 0.01 | N4: =+VLOOKUP(L4,'PRECIO PROVEEDORES'!$A$2:$B$716,2,0) -> 47093 | O4: =+M4*N4 -> 470.93 | Q4: Café | R4: 0.01 | S4: =+VLOOKUP(Q4,'PRECIO PROVEEDORES'!$A$2:$B$716,2,0) -> 47093 | T4: =+R4*S4 -> 470.93
B5: leche | C5: 0.14 | D5: =+VLOOKUP(B5,'PRECIO PROVEEDORES'!$A$2:$B$716,2,0) -> 1940 | E5: =+C5*D5 -> 271.6 | G5: leche | H5: 0.24 | I5: =+VLOOKUP(G5,'PRECIO PROVEEDORES'!$A$2:$B$716,2,0) -> 1940 | J5: =+H5*I5 -> 465.6 | L5: leche | M5: 0.21 | N5: =+VLOOKUP(L5,'PRECIO PROVEEDORES'!$A$2:$B$716,2,0) -> 1940 | O5: =+M5*N5 -> 407.4 | Q5: leche | R5: 0.1 | S5: =+VLOOKUP(Q5,'PRECIO PROVEEDORES'!$A$2:$B$716,2,0) -> 1940 | T5: =+R5*S5 -> 194
B11: Costo Total de la materia prima | E11: =SUM(E4:E10) -> 1166.367 | G11: Costo Total de la materia prima | J11: =SUM(J4:J10) -> 936.53 | L11: Costo Total de la materia prima | O11: =SUM(O4:O10) -> 878.33 | Q11: Costo Total de la materia prima | T11: =SUM(T4:T10) -> 664.93
B12: Costo total de la preparación | E12: =SUM(E11) -> 1166.367 | G12: Costo total de la preparación | J12: =SUM(J11) -> 936.53 | L12: Costo total de la preparación | O12: =SUM(O11) -> 878.33 | Q12: Costo total de la preparación | T12: =SUM(T11) -> 664.93
B13: Costo porción | E13: =+E12 -> 1166.367 | G13: Costo porción | J13: =+J12 -> 936.53 | L13: Costo porción | O13: =+O12 -> 878.33 | Q13: Costo porción | T13: =+T12 -> 664.93
B14: Porcentaje costo materia prima establecida | D14: 0.3 | G14: Porcentaje costo materia prima establecida | I14: 0.3 | L14: Porcentaje costo materia prima establecida | N14: 0.3 | Q14: Porcentaje costo materia prima establecida | S14: 0.3
B15: Precio potencial de venta | E15: =+E13*3.33333333333333 -> 3887.89 | G15: Precio potencial de venta | J15: =+J13*3.33333333333333 -> 3121.7667 | L15: Precio potencial de venta | O15: =+O13*3.33333333333333 -> 2927.7667 | Q15: Precio potencial de venta | T15: =+T13*3.33333333333333 -> 2216.4333
B16: Precio de Venta | E16: 6300 | G16: Precio de Venta | J16: 6100 | L16: Precio de Venta | O16: 5900 | Q16: Precio de Venta | T16: 4800
E17: =+E16-E15 -> 2412.11 | J17: =+J16-J15 -> 2978.2333 | O17: 5000 | T17: =+T16-T15 -> 2583.5667
B18: Costo Real MP | E18: =E13/E16 -> 0.18513762 | G18: Costo Real MP | J18: =J13/J16 -> 0.15352951 | L18: Costo Real MP | O18: =O13/O16 -> 0.14886949 | Q18: Costo Real MP | T18: =T13/T16 -> 0.13852708
B21: MOCHA | G21: MOCHA BLANCO | L21: LATTES CON SYRUPS (vainilla,caramel,hazelnut) | Q21: PINK LATTE, GOLDEN, INDIAN, MATCHA, CHOCO CHAI
C22: Kg/Lt/Uni | D22: $ | E22: Total $ | H22: Kg/Lt/Uni | I22: $ | J22: Total $ | M22: Kg/Lt/Uni | N22: $ | O22: Total $ | R22: Kg/Lt/Uni | S22: $ | T22: Total $
B23: Café | C23: 0.019 | D23: =+VLOOKUP(B23,'PRECIO PROVEEDORES'!$A$2:$B$716,2,0) -> 47093 | E23: =+C23*D23 -> 894.767 | G23: Café | H23: 0.019 | I23: =+VLOOKUP(G23,'PRECIO PROVEEDORES'!$A$2:$B$716,2,0) -> 47093 | J23: =+H23*I23 -> 894.767 | L23: Café | M23: 0.01 | N23: =+VLOOKUP(L23,'PRECIO PROVEEDORES'!$A$2:$B$716,2,0) -> 47093 | O23: =+M23*N23 -> 470.93 | Q23: lattes en polvo | R23: 0.003 | S23: =+VLOOKUP(Q23,'PRECIO PROVEEDORES'!$A$2:$B$716,2,0) -> 287980 | T23: =+R23*S23 -> 863.94
B24: leche | C24: 0.23 | D24: =+VLOOKUP(B24,'PRECIO PROVEEDORES'!$A$2:$B$716,2,0) -> 1940 | E24: =+C24*D24 -> 446.2 | G24: leche | H24: 0.23 | I24: =+VLOOKUP(G24,'PRECIO PROVEEDORES'!$A$2:$B$716,2,0) -> 1940 | J24: =+H24*I24 -> 446.2 | L24: leche | M24: 0.24 | N24: =+VLOOKUP(L24,'PRECIO PROVEEDORES'!$A$2:$B$716,2,0) -> 1940 | O24: =+M24*N24 -> 465.6 | Q24: leche | R24: 0.24 | S24: =+VLOOKUP(Q24,'PRECIO PROVEEDORES'!$A$2:$B$716,2,0) -> 1940 | T24: =+R24*S24 -> 465.6
B25: Chips alpino con leche | C25: 0.04 | D25: =+VLOOKUP(B25,'PRECIO PROVEEDORES'!$A$2:$B$716,2,0) -> 9561 | E25: =+C25*D25 -> 382.44 | G25: leche condensada | H25: 0.02 | I25: =+VLOOKUP(G25,'PRECIO PROVEEDORES'!$A$2:$B$716,2,0) -> 12675 | J25: =+H25*I25 -> 253.5 | L25: syrup | M25: 0.018 | N25: =+VLOOKUP(L25,'PRECIO PROVEEDORES'!$A$2:$B$716,2,0) -> 15388 | O25: =+M25*N25 -> 276.984
B30: Costo Total de la materia prima | E30: =SUM(E23:E29) -> 1723.407 | G30: Costo Total de la materia prima | J30: =SUM(J23:J29) -> 1594.467 | L30: Costo Total de la materia prima | O30: =SUM(O23:O29) -> 1213.514 | Q30: Costo Total de la materia prima | T30: =SUM(T23:T29) -> 1329.54
B31: Costo total de la preparación | E31: =SUM(E30) -> 1723.407 | G31: Costo total de la preparación | J31: =SUM(J30) -> 1594.467 | L31: Costo total de la preparación | O31: =SUM(O30) -> 1213.514 | Q31: Costo total de la preparación | T31: =SUM(T30) -> 1329.54
B32: Costo porción | E32: =+E31 -> 1723.407 | G32: Costo porción | J32: =+J31 -> 1594.467 | L32: Costo porción | O32: =+O31 -> 1213.514 | Q32: Costo porción | T32: =+T31 -> 1329.54
B33: Porcentaje costo materia prima establecida | D33: 0.3 | G33: Porcentaje costo materia prima establecida | I33: 0.3 | L33: Porcentaje costo materia prima establecida | N33: 0.3 | Q33: Porcentaje costo materia prima establecida | S33: 0.3 | U33: matcha | V33: 5800
B34: Precio potencial de venta | E34: =+E32*3.33333333333333 -> 5744.69 | G34: Precio potencial de venta | J34: =+J32*3.33333333333333 -> 5314.89 | L34: Precio potencial de venta | O34: =+O32*3.33333333333333 -> 4045.0467 | Q34: Precio potencial de venta | T34: =+T32*3.33333333333333 -> 4431.8
B35: Precio de Venta | C35: iced | E35: 6800 | G35: Precio de Venta | H35: iced | J35: 6800 | L35: Precio de Venta | O35: 6700 | Q35: Precio de Venta | T35: 6000
E36: =+E35-E34 -> 1055.31 | J36: =+J35-J34 -> 1485.11 | O36: =+O35-O34 -> 2654.9533 | T36: =+T35-T34 -> 1568.2
B37: Costo Real MP | E37: =E32/E35 -> 0.25344221 | G37: Costo Real MP | J37: =J32/J35 -> 0.23448044 | L37: Costo Real MP | O37: =O32/O35 -> 0.18112149 | Q37: Costo Real MP | T37: =T32/T35 -> 0.22159
B40: BABYCHINO | G40: CHOCO CALIENTE | L40: CHOCO BLANCO | Q40: CHAI LATTE
C41: Kg/Lt/Uni | D41: $ | E41: Total $ | H41: Kg/Lt/Uni | I41: $ | J41: Total $ | M41: Kg/Lt/Uni | N41: $ | O41: Total $ | R41: Kg/Lt/Uni | S41: $ | T41: Total $
B42: leche condensada | C42: 0.025 | D42: =+VLOOKUP(B42,'PRECIO PROVEEDORES'!$A$2:$B$716,2,0) -> 12675 | E42: =+C42*D42 -> 316.875 | G42: leche | H42: 0.23 | I42: =+VLOOKUP(G42,'PRECIO PROVEEDORES'!$A$2:$B$716,2,0) -> 1940 | J42: =+H42*I42 -> 446.2 | L42: leche | M42: 0.23 | N42: =+VLOOKUP(L42,'PRECIO PROVEEDORES'!$A$2:$B$716,2,0) -> 1940 | O42: =+M42*N42 -> 446.2 | Q42: leche | R42: 0.24 | S42: =+VLOOKUP(Q42,'PRECIO PROVEEDORES'!$A$2:$B$716,2,0) -> 1940 | T42: =+R42*S42 -> 465.6
B43: leche | C43: 0.21 | D43: =+VLOOKUP(B43,'PRECIO PROVEEDORES'!$A$2:$B$716,2,0) -> 1940 | E43: =+C43*D43 -> 407.4 | G43: syrup | H43: 0.052 | I43: =+VLOOKUP(G43,'PRECIO PROVEEDORES'!$A$2:$B$716,2,0) -> 15388 | J43: =+H43*I43 -> 800.176 | L43: leche condensada | M43: 0.04 | N43: =+VLOOKUP(L43,'PRECIO PROVEEDORES'!$A$2:$B$716,2,0) -> 12675 | O43: =+M43*N43 -> 507 | Q43: te buena vibra chai | R43: 0.003 | S43: =+VLOOKUP(Q43,'PRECIO PROVEEDORES'!$A$2:$B$716,2,0) -> 90016 | T43: =+R43*S43 -> 270.048
B44: malvaviscos | C44: 0.009 | D44: =+VLOOKUP(B44,'PRECIO PROVEEDORES'!$A$2:$B$716,2,0) -> 22687.5 | E44: =+C44*D44 -> 204.1875 | G44: Chips alpino con leche | H44: 0.025 | I44: =+VLOOKUP(G44,'PRECIO PROVEEDORES'!$A$2:$B$716,2,0) -> 9561 | J44: =+H44*I44 -> 239.025
B49: Costo Total de la materia prima | E49: =SUM(E42:E48) -> 928.4625 | G49: Costo Total de la materia prima | J49: =SUM(J42:J48) -> 1485.401 | L49: Costo Total de la materia prima | O49: =SUM(O42:O48) -> 953.2 | Q49: Costo Total de la materia prima | T49: =SUM(T42:T48) -> 735.648
B50: Costo total de la preparación | E50: =SUM(E49) -> 928.4625 | G50: Costo total de la preparación | J50: =SUM(J49) -> 1485.401 | L50: Costo total de la preparación | O50: =SUM(O49) -> 953.2 | Q50: Costo total de la preparación | T50: =SUM(T49) -> 735.648
B51: Costo porción | E51: =+E50 -> 928.4625 | G51: Costo porción | J51: =+J50 -> 1485.401 | L51: Costo porción | O51: =+O50 -> 953.2 | Q51: Costo porción | T51: =+T50 -> 735.648
B52: Porcentaje costo materia prima establecida | D52: 0.3 | G52: Porcentaje costo materia prima establecida | I52: 0.3 | L52: Porcentaje costo materia prima establecida | N52: 0.3 | Q52: Porcentaje costo materia prima establecida | S52: 0.3
B53: Precio potencial de venta | E53: =+E51*3.33333333333333 -> 3094.875 | G53: Precio potencial de venta | J53: =+J51*3.33333333333333 -> 4951.3367 | L53: Precio potencial de venta | O53: =+O51*3.33333333333333 -> 3177.3333 | Q53: Precio potencial de venta | T53: =+T51*3.33333333333333 -> 2452.16
B54: Precio de Venta | E54: 4100 | G54: Precio de Venta | J54: 6000 | L54: Precio de Venta | O54: 6000 | Q54: Precio de Venta | T54: 5900
E55: =+E54-E53 -> 1005.125 | J55: =+J54-J53 -> 1048.6633 | O55: =+O54-O53 -> 2822.6667 | T55: =+T54-T53 -> 3447.84
B56: Costo Real MP | E56: =E51/E54 -> 0.22645427 | G56: Costo Real MP | J56: =J51/J54 -> 0.24756683 | L56: Costo Real MP | O56: =O51/O54 -> 0.15886667 | Q56: Costo Real MP | T56: =T51/T54 -> 0.1246861
B59: DOPPIO | G59: AMERICANO DOBLE SHOT | L59: ESPRESSO SIMPLE | Q59: LUNGO
C60: Kg/Lt/Uni | D60: $ | E60: Total $ | H60: Kg/Lt/Uni | I60: $ | J60: Total $ | M60: Kg/Lt/Uni | N60: $ | O60: Total $ | R60: Kg/Lt/Uni | S60: $ | T60: Total $
...

Sheet PASTELERIA PARA TUESTE
B2: COOKIE DOBLE CHOCO | G2: TARTA CHOCOLATE Y PISTACHO | L2: MEDIALUNA 90 GRS
C3: Kg/Lt/Uni | D3: $ | E3: Total $ | H3: Kg/Lt/Uni | I3: $ | J3: Total $ | M3: Kg/Lt/Uni | N3: $ | O3: Total $
B4: manteca ramolac | C4: 0.45 | D4: =+VLOOKUP(B4,'PRECIO PROVEEDORES'!$A$2:$B$716,2,0) -> 13662 | E4: =+C4*D4 -> 6147.9 | G4: pistacho natural | H4: 0.004 | I4: =+VLOOKUP(G4,'PRECIO PROVEEDORES'!$A$2:$B$716,2,0) -> 78338 | J4: =+H4*I4 -> 313.352 | L4: harina 0000 | M4: 1.8 | N4: =+VLOOKUP(L4,'PRECIO PROVEEDORES'!$A$2:$B$716,2,0) -> 1043.22 | O4: =+M4*N4 -> 1877.796
B5: azucar | C5: 0.4 | D5: =+VLOOKUP(B5,'PRECIO PROVEEDORES'!$A$2:$B$716,2,0) -> 1352 | E5: =+C5*D5 -> 540.8 | G5: Fenix 83 ( con leche) | H5: 0.03 | I5: =+VLOOKUP(G5,'PRECIO PROVEEDORES'!$A$2:$B$716,2,0) -> 36068 | J5: =+H5*I5 -> 1082.04 | L5: harina 000 | M5: 0.2 | N5: =+VLOOKUP(L5,'PRECIO PROVEEDORES'!$A$2:$B$716,2,0) -> 890 | O5: =+M5*N5 -> 178
B6: Azucar negro | C6: 0.4 | D6: =+VLOOKUP(B6,'PRECIO PROVEEDORES'!$A$2:$B$716,2,0) -> 1624.77 | E6: =+C6*D6 -> 649.908 | G6: crema de leche | H6: 0.02 | I6: =+VLOOKUP(G6,'PRECIO PROVEEDORES'!$A$2:$B$716,2,0) -> 10203 | J6: =+H6*I6 -> 204.06 | L6: azucar | M6: 0.25 | N6: =+VLOOKUP(L6,'PRECIO PROVEEDORES'!$A$2:$B$716,2,0) -> 1352 | O6: =+M6*N6 -> 338
B7: Huevos | C7: 4 | D7: =+VLOOKUP(B7,'PRECIO PROVEEDORES'!$A$2:$B$716,2,0) -> 192 | E7: =+C7*D7 -> 768 | G7: miel | H7: 0.002 | I7: =+VLOOKUP(G7,'PRECIO PROVEEDORES'!$A$2:$B$716,2,0) -> 6062 | J7: =+H7*I7 -> 12.124 | L7: levadura seca | M7: 0.02 | N7: =+VLOOKUP(L7,'PRECIO PROVEEDORES'!$A$2:$B$716,2,0) -> 17780 | O7: =+M7*N7 -> 355.6
B8: harina 0000 | C8: 0.92 | D8: =+VLOOKUP(B8,'PRECIO PROVEEDORES'!$A$2:$B$716,2,0) -> 1043.22 | E8: =+C8*D8 -> 959.7624 | G8: frambuesa congelada | H8: 0.03 | I8: =+VLOOKUP(G8,'PRECIO PROVEEDORES'!$A$2:$B$716,2,0) -> 24829 | J8: =+H8*I8 -> 744.87 | L8: sal fina | M8: 0.04 | N8: =+VLOOKUP(L8,'PRECIO PROVEEDORES'!$A$2:$B$716,2,0) -> 1633 | O8: =+M8*N8 -> 65.32
B9: bicarbonato de sodio | C9: 0.01 | D9: =+VLOOKUP(B9,'PRECIO PROVEEDORES'!$A$2:$B$716,2,0) -> 2517 | E9: =+C9*D9 -> 25.17 | G9: azucar | H9: 0.01 | I9: =+VLOOKUP(G9,'PRECIO PROVEEDORES'!$A$2:$B$716,2,0) -> 1352 | J9: =+H9*I9 -> 13.52 | L9: leche | M9: 0.5 | N9: =+VLOOKUP(L9,'PRECIO PROVEEDORES'!$A$2:$B$716,2,0) -> 1940 | O9: =+M9*N9 -> 970
B10: Polvo para hornear | C10: 0.014 | D10: =+VLOOKUP(B10,'PRECIO PROVEEDORES'!$A$2:$B$716,2,0) -> 6040 | E10: =+C10*D10 -> 84.56 | L10: huevos | M10: 6 | N10: =+VLOOKUP(L10,'PRECIO PROVEEDORES'!$A$2:$B$716,2,0) -> 192 | O10: =+M10*N10 -> 1152
B11: sal fina | C11: 0.014 | D11: =+VLOOKUP(B11,'PRECIO PROVEEDORES'!$A$2:$B$716,2,0) -> 1633 | E11: =+C11*D11 -> 22.862 | L11: miel | M11: 0.06 | N11: =+VLOOKUP(L11,'PRECIO PROVEEDORES'!$A$2:$B$716,2,0) -> 6062 | O11: =+M11*N11 -> 363.72
B12: Fenix 83 ( con leche) | C12: 0.25 | D12: =+VLOOKUP(B12,'PRECIO PROVEEDORES'!$A$2:$B$716,2,0) -> 36068 | E12: =+C12*D12 -> 9017 | L12: manteca | M12: 0.57 | N12: =+VLOOKUP(L12,'PRECIO PROVEEDORES'!$A$2:$B$716,2,0) -> 12000 | O12: =+M12*N12 -> 6840
B13: Fenix 86 (semi amargo) | C13: 0.25 | D13: =+VLOOKUP(B13,'PRECIO PROVEEDORES'!$A$2:$B$716,2,0) -> 39988 | E13: =+C13*D13 -> 9997
B14: Esencia de vainilla | C14: 0.01 | D14: =+VLOOKUP(B14,'PRECIO PROVEEDORES'!$A$2:$B$716,2,0) -> 2118 | E14: =+C14*D14 -> 21.18
B19: Costo Total de la materia prima | E19: =SUM(E4:E18) -> 28234.142 | G19: Costo Total de la materia prima | J19: =SUM(J4:J18) -> 2369.966 | L19: Costo Total de la materia prima | O19: =SUM(O4:O18) -> 12140.436
B20: Costo total de la preparación | E20: =SUM(E19) -> 28234.142 | G20: Costo total de la preparación | J20: =SUM(J19) -> 2369.966 | L20: Costo total de la preparación | O20: =SUM(O19) -> 12140.436
B21: Costo porción | E21: =+E20/29 -> 973.59112 | G21: Costo porción | J21: =+J20 -> 2369.966 | L21: Costo porción | O21: =+O20/42 -> 289.058
B22: Porcentaje costo materia prima establecida | D22: 0.3 | G22: Porcentaje costo materia prima establecida | I22: 0.3 | L22: Porcentaje costo materia prima establecida | N22: 0.3
B23: Precio potencial de venta | E23: =+E21*3.33333333333333 -> 3245.3037 | G23: Precio potencial de venta | J23: =+J21*3.33333333333333 -> 7899.8867 | L23: Precio potencial de venta | O23: =+O21*3.33333333333333 -> 963.52667
B24: Precio de Venta a tueste | E24: 2140 | G24: Precio de Venta | J24: 6800 | O24: 1200
E25: =+E24-E23 -> -1105.3037 | J25: =+J24-J23 -> -1099.8867 | O25: =+O24-O23 -> 236.47333
B26: Costo Real MP | E26: =E21/E24 -> 0.45494912 | G26: Costo Real MP | J26: =J21/J24 -> 0.34852441 | L26: Costo Real MP | O26: =O21/O24 -> 0.24088167
B29: CROISSANT 140 grs | G29: COOKIE DE FRAMBUESA Y CHOCO BLANCO | L29: KEYLIME PIE
C30: Kg/Lt/Uni | D30: $ | E30: Total $ | H30: Kg/Lt/Uni | I30: $ | J30: Total $ | M30: Kg/Lt/Uni | N30: $ | O30: Total $
B31: harina 0000 | C31: 2 | D31: =+VLOOKUP(B31,'PRECIO PROVEEDORES'!$A$2:$B$716,2,0) -> 1043.22 | E31: =+C31*D31 -> 2086.44 | G31: manteca | H31: 0.32 | I31: =+VLOOKUP(G31,'PRECIO PROVEEDORES'!$A$2:$B$716,2,0) -> 12000 | J31: =+H31*I31 -> 3840 | L31: lima | M31: 0.265 | N31: =+VLOOKUP(L31,'PRECIO PROVEEDORES'!$A$2:$B$716,2,0) -> 5400 | O31: =+M31*N31 -> 1431
B32: harina 000 | C32: 0.5 | D32: =+VLOOKUP(B32,'PRECIO PROVEEDORES'!$A$2:$B$716,2,0) -> 890 | E32: =+C32*D32 -> 445 | G32: azucar | H32: 0.4 | I32: =+VLOOKUP(G32,'PRECIO PROVEEDORES'!$A$2:$B$716,2,0) -> 1352 | J32: =+H32*I32 -> 540.8 | L32: leche condensada | M32: 0.88 | N32: =+VLOOKUP(L32,'PRECIO PROVEEDORES'!$A$2:$B$716,2,0) -> 12675 | O32: =+M32*N32 -> 11154
B33: azucar | C33: 0.25 | D33: =+VLOOKUP(B33,'PRECIO PROVEEDORES'!$A$2:$B$716,2,0) -> 1352 | E33: =+C33*D33 -> 338 | G33: huevos | H33: 2 | I33: =+VLOOKUP(G33,'PRECIO PROVEEDORES'!$A$2:$B$716,2,0) -> 192 | J33: =+H33*I33 -> 384 | L33: huevos | M33: 6 | N33: =+VLOOKUP(L33,'PRECIO PROVEEDORES'!$A$2:$B$716,2,0) -> 192 | O33: =+M33*N33 -> 1152
B34: levadura seca | C34: 0.016 | D34: =+VLOOKUP(B34,'PRECIO PROVEEDORES'!$A$2:$B$716,2,0) -> 17780 | E34: =+C34*D34 -> 284.48 | G34: harina 0000 | H34: 0.535 | I34: =+VLOOKUP(G34,'PRECIO PROVEEDORES'!$A$2:$B$716,2,0) -> 1043.22 | J34: =+H34*I34 -> 558.1227 | L34: harina 000 | M34: 0.18 | N34: =+VLOOKUP(L34,'PRECIO PROVEEDORES'!$A$2:$B$716,2,0) -> 890 | O34: =+M34*N34 -> 160.2
B35: huevos | C35: 3 | D35: =+VLOOKUP(B35,'PRECIO PROVEEDORES'!$A$2:$B$716,2,0) -> 192 | E35: =+C35*D35 -> 576 | G35: Polvo para hornear | H35: 0.01 | I35: =+VLOOKUP(G35,'PRECIO PROVEEDORES'!$A$2:$B$716,2,0) -> 6040 | J35: =+H35*I35 -> 60.4 | L35: canela en polvo | M35: 0.001 | N35: =+VLOOKUP(L35,'PRECIO PROVEEDORES'!$A$2:$B$716,2,0) -> 10061.64 | O35: =+M35*N35 -> 10.06164
B36: manteca | C36: 0.7 | D36: =+VLOOKUP(B36,'PRECIO PROVEEDORES'!$A$2:$B$716,2,0) -> 12000 | E36: =+C36*D36 -> 8400 | G36: Esencia de vainilla | H36: 0.01 | I36: =+VLOOKUP(G36,'PRECIO PROVEEDORES'!$A$2:$B$716,2,0) -> 2118 | J36: =+H36*I36 -> 21.18 | L36: azucar | M36: 0.152 | N36: =+VLOOKUP(L36,'PRECIO PROVEEDORES'!$A$2:$B$716,2,0) -> 1352 | O36: =+M36*N36 -> 205.504
B37: sal fina | C37: 0.044 | D37: =+VLOOKUP(B37,'PRECIO PROVEEDORES'!$A$2:$B$716,2,0) -> 1633 | E37: =+C37*D37 -> 71.852 | G37: Fenix 90 blanco | H37: 0.2 | I37: =+VLOOKUP(G37,'PRECIO PROVEEDORES'!$A$2:$B$716,2,0) -> 34892 | J37: =+H37*I37 -> 6978.4 | L37: bicarbonato de sodio | M37: 0.003 | N37: =+VLOOKUP(L37,'PRECIO PROVEEDORES'!$A$2:$B$716,2,0) -> 2517 | O37: =+M37*N37 -> 7.551
G38: frambuesa congelada | H38: 0.12 | I38: =+VLOOKUP(G38,'PRECIO PROVEEDORES'!$A$2:$B$716,2,0) -> 24829 | J38: =+H38*I38 -> 2979.48 | L38: sal fina | M38: 0.001 | N38: =+VLOOKUP(L38,'PRECIO PROVEEDORES'!$A$2:$B$716,2,0) -> 1633 | O38: =+M38*N38 -> 1.633
B39: POR KG MASA | L39: manteca | M39: 0.167 | N39: =+VLOOKUP(L39,'PRECIO PROVEEDORES'!$A$2:$B$716,2,0) -> 12000 | O39: =+M39*N39 -> 2004
L40: leche | M40: 0.067 | N40: =+VLOOKUP(L40,'PRECIO PROVEEDORES'!$A$2:$B$716,2,0) -> 1940 | O40: =+M40*N40 -> 129.98
L41: miel | M41: 0.017 | N41: =+VLOOKUP(L41,'PRECIO PROVEEDORES'!$A$2:$B$716,2,0) -> 6062 | O41: =+M41*N41 -> 103.054
L42: Crema de leche | M42: 0.12 | N42: =+VLOOKUP(L42,'PRECIO PROVEEDORES'!$A$2:$B$716,2,0) -> 10203 | O42: =+M42*N42 -> 1224.36
L43: almendras | M43: 0.01 | N43: =+VLOOKUP(L43,'PRECIO PROVEEDORES'!$A$2:$B$716,2,0) -> 25872 | O43: =+M43*N43 -> 258.72
L44: Fenix 90 blanco | M44: 0.01 | N44: =+VLOOKUP(L44,'PRECIO PROVEEDORES'!$A$2:$B$716,2,0) -> 34892 | O44: =+M44*N44 -> 348.92
B46: Costo Total de la materia prima | E46: =SUM(E31:E45) -> 12201.772 | G46: Costo Total de la materia prima | J46: =SUM(J31:J45) -> 15362.383 | L46: Costo Total de la materia prima | O46: =SUM(O31:O45) -> 18190.984
B47: Costo total de la preparación | E47: =SUM(E46) -> 12201.772 | G47: Costo total de la preparación | J47: =SUM(J46) -> 15362.383 | L47: Costo total de la preparación | O47: =SUM(O46) -> 18190.984
B48: Costo porción | E48: =+E47/28 -> 435.77757 | G48: Costo porción | J48: =+J47/16 -> 960.14892 | L48: Costo porción | O48: =+O47/8 -> 2273.873
...

Sheet SUBRECETAS TUESTE  CP
B2: YOGURT GRIEGO rinde 6 porciones 150ml (1 LITRO yogurt) | G2: HUMMUS DE REMOLACHA | L2: PAN DE CHIPA | Q2: MERMELADA DE MORRON
C3: Kg/Lt/Uni | D3: $ | E3: Total $ | H3: Kg/Lt/Uni | I3: $ | J3: Total $ | M3: Kg/Lt/Uni | N3: $ | O3: Total $ | R3: Kg/Lt/Uni | S3: $ | T3: Total $
B4: Leche | C4: 1.5 | D4: =+VLOOKUP(B4,'PRECIO PROVEEDORES'!$A$2:$B$716,2,0) -> 1940 | E4: =+C4*D4 -> 2910 | G4: garbanzos | H4: 0.4 | I4: =+VLOOKUP(G4,'PRECIO PROVEEDORES'!$A$2:$B$716,2,0) -> 3330 | J4: =+H4*I4 -> 1332 | L4: Fecula de mandioca | M4: 1 | N4: =+VLOOKUP(L4,'PRECIO PROVEEDORES'!$A$2:$B$716,2,0) -> 4134 | O4: =+M4*N4 -> 4134 | Q4: Aji colorado | R4: 1 | S4: =+VLOOKUP(Q4,'PRECIO PROVEEDORES'!$A$2:$B$716,2,0) -> 4788 | T4: =+R4*S4 -> 4788
B5: leche en polvo | C5: 0.08 | D5: =+VLOOKUP(B5,'PRECIO PROVEEDORES'!$A$2:$B$716,2,0) -> 12915 | E5: =+C5*D5 -> 1033.2 | G5: polvo de remolacha | H5: 0.02 | I5: =+VLOOKUP(G5,'PRECIO PROVEEDORES'!$A$2:$B$716,2,0) -> 16900 | J5: =+H5*I5 -> 338 | L5: manteca tueste alyser | M5: 0.4 | N5: =+VLOOKUP(L5,'PRECIO PROVEEDORES'!$A$2:$B$716,2,0) -> 12206 | O5: =+M5*N5 -> 4882.4 | Q5: azucar | R5: 0.1 | S5: =+VLOOKUP(Q5,'PRECIO PROVEEDORES'!$A$2:$B$716,2,0) -> 1352 | T5: =+R5*S5 -> 135.2
B6: yogur dahi natural | C6: 0.4 | D6: =+VLOOKUP(B6,'PRECIO PROVEEDORES'!$A$2:$B$716,2,0) -> 8765 | E6: =+C6*D6 -> 3506 | G6: curry | H6: 0.01 | I6: =+VLOOKUP(G6,'PRECIO PROVEEDORES'!$A$2:$B$716,2,0) -> 5009.4 | J6: =+H6*I6 -> 50.094 | L6: huevos | M6: 6 | N6: =+VLOOKUP(L6,'PRECIO PROVEEDORES'!$A$2:$B$716,2,0) -> 192 | O6: =+M6*N6 -> 1152 | Q6: Pimienta negra en granos | R6: 0.005 | S6: =+VLOOKUP(Q6,'PRECIO PROVEEDORES'!$A$2:$B$716,2,0) -> 22269 | T6: =+R6*S6 -> 111.345
B7: porcion | C7: 0.15 | G7: jugo de limon | H7: 0.015 | I7: =+VLOOKUP(G7,'PRECIO PROVEEDORES'!$A$2:$B$716,2,0) -> 6125 | J7: =+H7*I7 -> 91.875 | L7: pategras | M7: 0.25 | N7: =+VLOOKUP(L7,'PRECIO PROVEEDORES'!$A$2:$B$716,2,0) -> 16000 | O7: =+M7*N7 -> 4000 | Q7: Pimienta negra en granos | R7: 0.005 | S7: =+VLOOKUP(Q7,'PRECIO PROVEEDORES'!$A$2:$B$716,2,0) -> 22269 | T7: =+R7*S7 -> 111.345
B8: rinde | C8: 1 | E8: =SUM(E4:E6) -> 7449.2 | G8: ajo | H8: 0.1 | I8: =+VLOOKUP(G8,'PRECIO PROVEEDORES'!$A$2:$B$716,2,0) -> 1800 | J8: =+H8*I8 -> 180 | L8: queso Reggianito | M8: 0.25 | N8: =+VLOOKUP(L8,'PRECIO PROVEEDORES'!$A$2:$B$716,2,0) -> 17376 | O8: =+M8*N8 -> 4344 | Q8: sal fina | R8: 0.005 | S8: =+VLOOKUP(Q8,'PRECIO PROVEEDORES'!$A$2:$B$716,2,0) -> 1633 | T8: =+R8*S8 -> 8.165
G9: sal fina | H9: 0.005 | I9: =+VLOOKUP(G9,'PRECIO PROVEEDORES'!$A$2:$B$716,2,0) -> 1633 | J9: =+H9*I9 -> 8.165 | L9: queso danbo tregar | M9: 0.5 | N9: =+VLOOKUP(L9,'PRECIO PROVEEDORES'!$A$2:$B$716,2,0) -> 10697 | O9: =+M9*N9 -> 5348.5
B10: rinde 6 porciones de 150gm c/u. de la receta sale de aprox. | G10: aceite de oliva | H10: 0.01 | I10: =+VLOOKUP(G10,'PRECIO PROVEEDORES'!$A$2:$B$716,2,0) -> 16595 | J10: =+H10*I10 -> 165.95 | L10: sal fina | M10: 0.01 | N10: =+VLOOKUP(L10,'PRECIO PROVEEDORES'!$A$2:$B$716,2,0) -> 1633 | O10: =+M10*N10 -> 16.33
B11: 970gm a 1000gm con un desperdicio de 700 gm de yogurt filtrado. | Q11: total receta 1.115kg | T11: =SUM(T4:T8) -> 5154.055
G12: rinde | J12: =SUM(J4:J10) -> 2166.084 | Q12: por kg | T12: =T11*1000/1115 -> 4622.4709
G13: x 1 kg | J13: =J12*1000/400 -> 5415.21 | L13: rinde 15 panes de 180grs | O13: =SUM(O4:O10) -> 23877.23
L14: por unidad | O14: =O13/15 -> 1591.8153
L15: por kg | O15: =O13*1000/2700 -> 8843.4185
B21: GRANOLA | G21: PESTO DE TOMATES | L21: CHERRYS CONFITADOS | Q21: MEDIALUNA 90 GRS
C22: Kg/Lt/Uni | D22: $ | E22: Total $ | H22: Kg/Lt/Uni | I22: $ | J22: Total $ | M22: Kg/Lt/Uni | N22: $ | O22: Total $ | R22: Kg/Lt/Uni | S22: $ | T22: Total $
B23: Almendras | C23: 0.25 | D23: =+VLOOKUP(B23,'PRECIO PROVEEDORES'!$A$2:$B$716,2,0) -> 25872 | E23: =+C23*D23 -> 6468 | G23: tomate seco | H23: 0.2 | I23: =+VLOOKUP(G23,'PRECIO PROVEEDORES'!$A$2:$B$716,2,0) -> 17587.35 | J23: =+H23*I23 -> 3517.47 | L23: Tomate cherry rojo | M23: 0.5 | N23: =+VLOOKUP(L23,'PRECIO PROVEEDORES'!$A$2:$B$716,2,0) -> 4095 | O23: =+M23*N23 -> 2047.5 | Q23: harina 0000 | R23: 1.8 | S23: =+VLOOKUP(Q23,'PRECIO PROVEEDORES'!$A$2:$B$716,2,0) -> 1043.22 | T23: =+R23*S23 -> 1877.796
B24: Nueces cuartos | C24: 0.25 | D24: =+VLOOKUP(B24,'PRECIO PROVEEDORES'!$A$2:$B$716,2,0) -> 27769.5 | E24: =+C24*D24 -> 6942.375 | G24: ajo | H24: 1 | I24: =+VLOOKUP(G24,'PRECIO PROVEEDORES'!$A$2:$B$716,2,0) -> 1800 | J24: =+H24*I24 -> 1800 | L24: sal fina | M24: 0.02 | N24: =+VLOOKUP(L24,'PRECIO PROVEEDORES'!$A$2:$B$716,2,0) -> 1633 | O24: =+M24*N24 -> 32.66 | Q24: harina 000 | R24: 0.2 | S24: =+VLOOKUP(Q24,'PRECIO PROVEEDORES'!$A$2:$B$716,2,0) -> 890 | T24: =+R24*S24 -> 178
B25: Mix de semillas | C25: 0.35 | D25: =+VLOOKUP(B25,'PRECIO PROVEEDORES'!$A$2:$B$716,2,0) -> 5952.89 | E25: =+C25*D25 -> 2083.5115 | G25: aceite de girasol | H25: 0.1 | I25: =+VLOOKUP(G25,'PRECIO PROVEEDORES'!$A$2:$B$716,2,0) -> 4299.01 | J25: =+H25*I25 -> 429.901 | L25: Hierbas frescas, Tomillo | M25: 0.1 | N25: =+VLOOKUP(L25,'PRECIO PROVEEDORES'!$A$2:$B$716,2,0) -> 3146 | O25: =+M25*N25 -> 314.6 | Q25: azucar | R25: 0.25 | S25: =+VLOOKUP(Q25,'PRECIO PROVEEDORES'!$A$2:$B$716,2,0) -> 1352 | T25: =+R25*S25 -> 338
